Workbook

Sheet Onboarding Tracker
A1: CLIENT ONBOARDING — PROJECT WORK BREAKDOWN TRACKER
A2: Project Title | F2: Company
A3: Project Manager | F3: Date
A5: STATUS LEGEND
A6: Not Started | C6: In Progress | E6: Blocked | G6: Complete | I6: N/A
A8: # | B8: ID | C8: Deliverable / Task | D8: Status | E8: Task Owner | F8: Start Date | G8: End Date | H8: Blocking Points | I8: Comments / Notes
A9: 1. PROJECT CONCEPTION & INITIATION
B10: 1.1 | C10: Project Charter Validation | D10: Not Started
B11: 1.2 | C11: Stakeholder Register | D11: Not Started
B12: 1.3 | C12: Kick-Off Meeting | D12: Not Started
B13: 1.4 | C13: Tech & Commercial Communication Channel Setup | D13: Not Started
A14: 2. PROJECT DEFINITION & PLANNING
A15: 2.1 Technical Integration — [Product A]
B16: 2.1.1 | C16: Technical Meeting | D16: Not Started
B17: 2.1.2 | C17: Technical Integration Setup | D17: Not Started
B18: 2.1.3 | C18: API Access Creation | D18: Not Started
B19: 2.1.4 | C19: Testing (Test Environment) | D19: Not Started
B20: 2.1.5 | C20: Go-Live (Production Environment) | D20: Not Started
C21: Dashboard Creation with Access | D21: Not Started
C22: Dashboard Training | D22: Not Started
C23: Invoice Explanation | D23: Not Started
C24: Feature Activation | D24: Not Started
C25: IP Collection / Activation | D25: Not Started
C26: Additional Setup Tasks (etc.) | D26: Not Started
A27: 2.2 Setup — [Product B]
B28: 2.2.1 | C28: Intro to Product B Manager | D28: Not Started
C29: Access to Portal | D29: Not Started
C30: Dashboard Training | D30: Not Started
C31: Device / Phone Setup | D31: Not Started
C32: Reporting Configuration | D32: Not Started
C33: Market Rules / Guidelines Sharing | D33: Not Started
C34: Additional Setup Tasks (etc.) | D34: Not Started
A35: 2.3 Setup — [Product C]
A36: 3. PROJECT COMMUNICATION PLAN
B37: 3.1.1 | C37: Follow-Up Emails | D37: Not Started
B38: 3.1.2 | C38: Weekly / Bi-Weekly Calls | D38: Not Started
C39: Status Update Rules to Client | D39: Not Started
C40: Status Update — Internal | D40: Not Started
C41: Technical Documentation Creation | D41: Not Started
C42: Business Review (Quarterly) | D42: Not Started
...

Sheet Summary Dashboard
A1: ONBOARDING SUMMARY DASHBOARD
A2: Update statuses in the Onboarding Tracker sheet — this sheet shows live progress per phase.
A4: Phase | B4: Total Tasks | C4: Complete | D4: In Progress | E4: Blocked | F4: % Complete
A5: 1. Project Conception & Initiation | B5: =COUNTA('Onboarding Tracker'!C9:C12)-COUNTIF('Onboarding Tracker'!C9:C12,"") -> 2 | C5: =COUNTIF('Onboarding Tracker'!D9:D12,"Complete") -> 0 | D5: =COUNTIF('Onboarding Tracker'!D9:D12,"In Progress") -> 0 | E5: =COUNTIF('Onboarding Tracker'!D9:D12,"Blocked") -> 0 | F5: =IF(B5=0,0,C5/B5) -> 0
A6: 2. Project Definition & Planning | B6: =COUNTA('Onboarding Tracker'!C14:C27)-COUNTIF('Onboarding Tracker'!C14:C27,"") -> 8 | C6: =COUNTIF('Onboarding Tracker'!D14:D27,"Complete") -> 0 | D6: =COUNTIF('Onboarding Tracker'!D14:D27,"In Progress") -> 0 | E6: =COUNTIF('Onboarding Tracker'!D14:D27,"Blocked") -> 0 | F6: =IF(B6=0,0,C6/B6) -> 0
A7: 3. Project Communication Plan | B7: =COUNTA('Onboarding Tracker'!C29:C36)-COUNTIF('Onboarding Tracker'!C29:C36,"") -> 4 | C7: =COUNTIF('Onboarding Tracker'!D29:D36,"Complete") -> 0 | D7: =COUNTIF('Onboarding Tracker'!D29:D36,"In Progress") -> 0 | E7: =COUNTIF('Onboarding Tracker'!D29:D36,"Blocked") -> 0 | F7: =IF(B7=0,0,C7/B7) -> 0
A8: 4. Sales & CSM Actions | B8: =COUNTA('Onboarding Tracker'!C38:C41)-COUNTIF('Onboarding Tracker'!C38:C41,"") -> 4 | C8: =COUNTIF('Onboarding Tracker'!D38:D41,"Complete") -> 0 | D8: =COUNTIF('Onboarding Tracker'!D38:D41,"In Progress") -> 0 | E8: =COUNTIF('Onboarding Tracker'!D38:D41,"Blocked") -> 0 | F8: =IF(B8=0,0,C8/B8) -> 0
A9: 5. Project Team Checklist | B9: =COUNTA('Onboarding Tracker'!C43:C50)-COUNTIF('Onboarding Tracker'!C43:C50,"") -> 4 | C9: =COUNTIF('Onboarding Tracker'!D43:D50,"Complete") -> 0 | D9: =COUNTIF('Onboarding Tracker'!D43:D50,"In Progress") -> 0 | E9: =COUNTIF('Onboarding Tracker'!D43:D50,"Blocked") -> 0 | F9: =IF(B9=0,0,C9/B9) -> 0
A10: 6. Project Execution & Monitoring | B10: =COUNTA('Onboarding Tracker'!C52:C55)-COUNTIF('Onboarding Tracker'!C52:C55,"") -> 4 | C10: =COUNTIF('Onboarding Tracker'!D52:D55,"Complete") -> 0 | D10: =COUNTIF('Onboarding Tracker'!D52:D55,"In Progress") -> 0 | E10: =COUNTIF('Onboarding Tracker'!D52:D55,"Blocked") -> 0 | F10: =IF(B10=0,0,C10/B10) -> 0
A11: 7. Project Closure | B11: =COUNTA('Onboarding Tracker'!C57:C60)-COUNTIF('Onboarding Tracker'!C57:C60,"") -> 2 | C11: =COUNTIF('Onboarding Tracker'!D57:D60,"Complete") -> 0 | D11: =COUNTIF('Onboarding Tracker'!D57:D60,"In Progress") -> 0 | E11: =COUNTIF('Onboarding Tracker'!D57:D60,"Blocked") -> 0 | F11: =IF(B11=0,0,C11/B11) -> 0
A12: TOTAL | B12: =SUM(B5:B11) -> 28 | C12: =SUM(C5:C11) -> 0 | D12: =SUM(D5:D11) -> 0 | E12: =SUM(E5:E11) -> 0 | F12: =IF(B12=0,0,C12/B12) -> 0
